2025-04-07 15:38:28,417 INFO    MainThread:784255 [wandb_init.py:setup_run_log_directory():662] Logging user logs to /mnt/W-PANCDR/src/wandb/run-20250407_153828-2cma53se/logs/debug.log
2025-04-07 15:38:28,417 INFO    MainThread:784255 [wandb_init.py:setup_run_log_directory():663] Logging internal logs to /mnt/W-PANCDR/src/wandb/run-20250407_153828-2cma53se/logs/debug-internal.log
2025-04-07 15:38:28,417 INFO    MainThread:784255 [wandb_init.py:init():781] calling init triggers
2025-04-07 15:38:28,417 INFO    MainThread:784255 [wandb_init.py:init():786] wandb.init called with sweep_config: {}
config: {'nz': 128, 'd_dim': 128, 'lr': 0.0001, 'lr_adv': 0.0001, 'lam': 0.01, 'batch_size': [128, 14], '_wandb': {}}
2025-04-07 15:38:28,417 INFO    MainThread:784255 [wandb_init.py:init():809] starting backend
2025-04-07 15:38:28,417 INFO    MainThread:784255 [wandb_init.py:init():813] sending inform_init request
2025-04-07 15:38:28,417 INFO    MainThread:784255 [backend.py:_multiprocessing_setup():101] multiprocessing start_methods=fork,spawn,forkserver, using: spawn
2025-04-07 15:38:28,417 INFO    MainThread:784255 [wandb_init.py:init():823] backend started and connected
2025-04-07 15:38:28,418 INFO    MainThread:784255 [wandb_init.py:init():915] updated telemetry
2025-04-07 15:38:28,750 INFO    MainThread:784255 [wandb_init.py:init():939] communicating run to backend with 90.0 second timeout
2025-04-07 15:38:29,467 INFO    MainThread:784255 [wandb_init.py:init():1014] starting run threads in backend
2025-04-07 15:38:29,565 INFO    MainThread:784255 [wandb_run.py:_console_start():2454] atexit reg
2025-04-07 15:38:29,566 INFO    MainThread:784255 [wandb_run.py:_redirect():2306] redirect: wrap_raw
2025-04-07 15:38:29,566 INFO    MainThread:784255 [wandb_run.py:_redirect():2371] Wrapping output streams.
2025-04-07 15:38:29,566 INFO    MainThread:784255 [wandb_run.py:_redirect():2394] Redirects installed.
2025-04-07 15:38:29,567 INFO    MainThread:784255 [wandb_init.py:init():1056] run started, returning control to user process
2025-04-07 15:39:49,054 INFO    MsgRouterThr:784255 [mailbox.py:close():129] [no run ID] Closing mailbox, abandoning 3 handles.
2025-04-07 15:39:49,775 ERROR   MainThread:784255 [redirect.py:_on_write():661] [no run ID] error in stderr callback
Traceback (most recent call last):
  File "/usr/local/lib/python3.8/dist-packages/wandb/sdk/lib/redirect.py", line 659, in _on_write
    cb(written_data)
  File "/usr/local/lib/python3.8/dist-packages/wandb/sdk/wandb_run.py", line 2381, in <lambda>
    lambda data: self._console_raw_callback("stderr", data),
  File "/usr/local/lib/python3.8/dist-packages/wandb/sdk/wandb_run.py", line 387, in wrapper
    return func(self, *args, **kwargs)
  File "/usr/local/lib/python3.8/dist-packages/wandb/sdk/wandb_run.py", line 435, in wrapper_fn
    return func(self, *args, **kwargs)
  File "/usr/local/lib/python3.8/dist-packages/wandb/sdk/wandb_run.py", line 1518, in _console_raw_callback
    self._backend.interface.publish_output_raw(name, data)
  File "/usr/local/lib/python3.8/dist-packages/wandb/sdk/interface/interface.py", line 761, in publish_output_raw
    self._publish_output_raw(o)
  File "/usr/local/lib/python3.8/dist-packages/wandb/sdk/interface/interface_shared.py", line 38, in _publish_output_raw
    self._publish(rec)
  File "/usr/local/lib/python3.8/dist-packages/wandb/sdk/interface/interface_sock.py", line 39, in _publish
    self._sock_client.send_record_publish(record)
  File "/usr/local/lib/python3.8/dist-packages/wandb/sdk/lib/sock_client.py", line 174, in send_record_publish
    self.send_server_request(server_req)
  File "/usr/local/lib/python3.8/dist-packages/wandb/sdk/lib/sock_client.py", line 154, in send_server_request
    self._send_message(msg)
  File "/usr/local/lib/python3.8/dist-packages/wandb/sdk/lib/sock_client.py", line 151, in _send_message
    self._sendall_with_error_handle(header + data)
  File "/usr/local/lib/python3.8/dist-packages/wandb/sdk/lib/sock_client.py", line 130, in _sendall_with_error_handle
    sent = self._sock.send(data)
BrokenPipeError: [Errno 32] Broken pipe
2025-04-07 15:39:49,776 ERROR   MainThread:784255 [redirect.py:_on_write():661] [no run ID] error in stderr callback
Traceback (most recent call last):
  File "/usr/local/lib/python3.8/dist-packages/wandb/sdk/lib/redirect.py", line 659, in _on_write
    cb(written_data)
  File "/usr/local/lib/python3.8/dist-packages/wandb/sdk/wandb_run.py", line 2381, in <lambda>
    lambda data: self._console_raw_callback("stderr", data),
  File "/usr/local/lib/python3.8/dist-packages/wandb/sdk/wandb_run.py", line 387, in wrapper
    return func(self, *args, **kwargs)
  File "/usr/local/lib/python3.8/dist-packages/wandb/sdk/wandb_run.py", line 435, in wrapper_fn
    return func(self, *args, **kwargs)
  File "/usr/local/lib/python3.8/dist-packages/wandb/sdk/wandb_run.py", line 1518, in _console_raw_callback
    self._backend.interface.publish_output_raw(name, data)
  File "/usr/local/lib/python3.8/dist-packages/wandb/sdk/interface/interface.py", line 761, in publish_output_raw
    self._publish_output_raw(o)
  File "/usr/local/lib/python3.8/dist-packages/wandb/sdk/interface/interface_shared.py", line 38, in _publish_output_raw
    self._publish(rec)
  File "/usr/local/lib/python3.8/dist-packages/wandb/sdk/interface/interface_sock.py", line 39, in _publish
    self._sock_client.send_record_publish(record)
  File "/usr/local/lib/python3.8/dist-packages/wandb/sdk/lib/sock_client.py", line 174, in send_record_publish
    self.send_server_request(server_req)
  File "/usr/local/lib/python3.8/dist-packages/wandb/sdk/lib/sock_client.py", line 154, in send_server_request
    self._send_message(msg)
  File "/usr/local/lib/python3.8/dist-packages/wandb/sdk/lib/sock_client.py", line 151, in _send_message
    self._sendall_with_error_handle(header + data)
  File "/usr/local/lib/python3.8/dist-packages/wandb/sdk/lib/sock_client.py", line 130, in _sendall_with_error_handle
    sent = self._sock.send(data)
BrokenPipeError: [Errno 32] Broken pipe
2025-04-07 15:39:49,777 ERROR   MainThread:784255 [redirect.py:_on_write():661] [no run ID] error in stderr callback
Traceback (most recent call last):
  File "/usr/local/lib/python3.8/dist-packages/wandb/sdk/lib/redirect.py", line 659, in _on_write
    cb(written_data)
  File "/usr/local/lib/python3.8/dist-packages/wandb/sdk/wandb_run.py", line 2381, in <lambda>
    lambda data: self._console_raw_callback("stderr", data),
  File "/usr/local/lib/python3.8/dist-packages/wandb/sdk/wandb_run.py", line 387, in wrapper
    return func(self, *args, **kwargs)
  File "/usr/local/lib/python3.8/dist-packages/wandb/sdk/wandb_run.py", line 435, in wrapper_fn
    return func(self, *args, **kwargs)
  File "/usr/local/lib/python3.8/dist-packages/wandb/sdk/wandb_run.py", line 1518, in _console_raw_callback
    self._backend.interface.publish_output_raw(name, data)
  File "/usr/local/lib/python3.8/dist-packages/wandb/sdk/interface/interface.py", line 761, in publish_output_raw
    self._publish_output_raw(o)
  File "/usr/local/lib/python3.8/dist-packages/wandb/sdk/interface/interface_shared.py", line 38, in _publish_output_raw
    self._publish(rec)
  File "/usr/local/lib/python3.8/dist-packages/wandb/sdk/interface/interface_sock.py", line 39, in _publish
    self._sock_client.send_record_publish(record)
  File "/usr/local/lib/python3.8/dist-packages/wandb/sdk/lib/sock_client.py", line 174, in send_record_publish
    self.send_server_request(server_req)
  File "/usr/local/lib/python3.8/dist-packages/wandb/sdk/lib/sock_client.py", line 154, in send_server_request
    self._send_message(msg)
  File "/usr/local/lib/python3.8/dist-packages/wandb/sdk/lib/sock_client.py", line 151, in _send_message
    self._sendall_with_error_handle(header + data)
  File "/usr/local/lib/python3.8/dist-packages/wandb/sdk/lib/sock_client.py", line 130, in _sendall_with_error_handle
    sent = self._sock.send(data)
BrokenPipeError: [Errno 32] Broken pipe
2025-04-07 15:39:49,777 ERROR   MainThread:784255 [redirect.py:_on_write():661] [no run ID] error in stderr callback
Traceback (most recent call last):
  File "/usr/local/lib/python3.8/dist-packages/wandb/sdk/lib/redirect.py", line 659, in _on_write
    cb(written_data)
  File "/usr/local/lib/python3.8/dist-packages/wandb/sdk/wandb_run.py", line 2381, in <lambda>
    lambda data: self._console_raw_callback("stderr", data),
  File "/usr/local/lib/python3.8/dist-packages/wandb/sdk/wandb_run.py", line 387, in wrapper
    return func(self, *args, **kwargs)
  File "/usr/local/lib/python3.8/dist-packages/wandb/sdk/wandb_run.py", line 435, in wrapper_fn
    return func(self, *args, **kwargs)
  File "/usr/local/lib/python3.8/dist-packages/wandb/sdk/wandb_run.py", line 1518, in _console_raw_callback
    self._backend.interface.publish_output_raw(name, data)
  File "/usr/local/lib/python3.8/dist-packages/wandb/sdk/interface/interface.py", line 761, in publish_output_raw
    self._publish_output_raw(o)
  File "/usr/local/lib/python3.8/dist-packages/wandb/sdk/interface/interface_shared.py", line 38, in _publish_output_raw
    self._publish(rec)
  File "/usr/local/lib/python3.8/dist-packages/wandb/sdk/interface/interface_sock.py", line 39, in _publish
    self._sock_client.send_record_publish(record)
  File "/usr/local/lib/python3.8/dist-packages/wandb/sdk/lib/sock_client.py", line 174, in send_record_publish
    self.send_server_request(server_req)
  File "/usr/local/lib/python3.8/dist-packages/wandb/sdk/lib/sock_client.py", line 154, in send_server_request
    self._send_message(msg)
  File "/usr/local/lib/python3.8/dist-packages/wandb/sdk/lib/sock_client.py", line 151, in _send_message
    self._sendall_with_error_handle(header + data)
  File "/usr/local/lib/python3.8/dist-packages/wandb/sdk/lib/sock_client.py", line 130, in _sendall_with_error_handle
    sent = self._sock.send(data)
BrokenPipeError: [Errno 32] Broken pipe
2025-04-07 15:39:49,777 ERROR   MainThread:784255 [redirect.py:_on_write():661] [no run ID] error in stderr callback
Traceback (most recent call last):
  File "/usr/local/lib/python3.8/dist-packages/wandb/sdk/lib/redirect.py", line 659, in _on_write
    cb(written_data)
  File "/usr/local/lib/python3.8/dist-packages/wandb/sdk/wandb_run.py", line 2381, in <lambda>
    lambda data: self._console_raw_callback("stderr", data),
  File "/usr/local/lib/python3.8/dist-packages/wandb/sdk/wandb_run.py", line 387, in wrapper
    return func(self, *args, **kwargs)
  File "/usr/local/lib/python3.8/dist-packages/wandb/sdk/wandb_run.py", line 435, in wrapper_fn
    return func(self, *args, **kwargs)
  File "/usr/local/lib/python3.8/dist-packages/wandb/sdk/wandb_run.py", line 1518, in _console_raw_callback
    self._backend.interface.publish_output_raw(name, data)
  File "/usr/local/lib/python3.8/dist-packages/wandb/sdk/interface/interface.py", line 761, in publish_output_raw
    self._publish_output_raw(o)
  File "/usr/local/lib/python3.8/dist-packages/wandb/sdk/interface/interface_shared.py", line 38, in _publish_output_raw
    self._publish(rec)
  File "/usr/local/lib/python3.8/dist-packages/wandb/sdk/interface/interface_sock.py", line 39, in _publish
    self._sock_client.send_record_publish(record)
  File "/usr/local/lib/python3.8/dist-packages/wandb/sdk/lib/sock_client.py", line 174, in send_record_publish
    self.send_server_request(server_req)
  File "/usr/local/lib/python3.8/dist-packages/wandb/sdk/lib/sock_client.py", line 154, in send_server_request
    self._send_message(msg)
  File "/usr/local/lib/python3.8/dist-packages/wandb/sdk/lib/sock_client.py", line 151, in _send_message
    self._sendall_with_error_handle(header + data)
  File "/usr/local/lib/python3.8/dist-packages/wandb/sdk/lib/sock_client.py", line 130, in _sendall_with_error_handle
    sent = self._sock.send(data)
BrokenPipeError: [Errno 32] Broken pipe
2025-04-07 15:39:49,777 ERROR   MainThread:784255 [redirect.py:_on_write():661] [no run ID] error in stderr callback
Traceback (most recent call last):
  File "/usr/local/lib/python3.8/dist-packages/wandb/sdk/lib/redirect.py", line 659, in _on_write
    cb(written_data)
  File "/usr/local/lib/python3.8/dist-packages/wandb/sdk/wandb_run.py", line 2381, in <lambda>
    lambda data: self._console_raw_callback("stderr", data),
  File "/usr/local/lib/python3.8/dist-packages/wandb/sdk/wandb_run.py", line 387, in wrapper
    return func(self, *args, **kwargs)
  File "/usr/local/lib/python3.8/dist-packages/wandb/sdk/wandb_run.py", line 435, in wrapper_fn
    return func(self, *args, **kwargs)
  File "/usr/local/lib/python3.8/dist-packages/wandb/sdk/wandb_run.py", line 1518, in _console_raw_callback
    self._backend.interface.publish_output_raw(name, data)
  File "/usr/local/lib/python3.8/dist-packages/wandb/sdk/interface/interface.py", line 761, in publish_output_raw
    self._publish_output_raw(o)
  File "/usr/local/lib/python3.8/dist-packages/wandb/sdk/interface/interface_shared.py", line 38, in _publish_output_raw
    self._publish(rec)
  File "/usr/local/lib/python3.8/dist-packages/wandb/sdk/interface/interface_sock.py", line 39, in _publish
    self._sock_client.send_record_publish(record)
  File "/usr/local/lib/python3.8/dist-packages/wandb/sdk/lib/sock_client.py", line 174, in send_record_publish
    self.send_server_request(server_req)
  File "/usr/local/lib/python3.8/dist-packages/wandb/sdk/lib/sock_client.py", line 154, in send_server_request
    self._send_message(msg)
  File "/usr/local/lib/python3.8/dist-packages/wandb/sdk/lib/sock_client.py", line 151, in _send_message
    self._sendall_with_error_handle(header + data)
  File "/usr/local/lib/python3.8/dist-packages/wandb/sdk/lib/sock_client.py", line 130, in _sendall_with_error_handle
    sent = self._sock.send(data)
BrokenPipeError: [Errno 32] Broken pipe
2025-04-07 15:39:49,778 ERROR   MainThread:784255 [redirect.py:_on_write():661] [no run ID] error in stderr callback
Traceback (most recent call last):
  File "/usr/local/lib/python3.8/dist-packages/wandb/sdk/lib/redirect.py", line 659, in _on_write
    cb(written_data)
  File "/usr/local/lib/python3.8/dist-packages/wandb/sdk/wandb_run.py", line 2381, in <lambda>
    lambda data: self._console_raw_callback("stderr", data),
  File "/usr/local/lib/python3.8/dist-packages/wandb/sdk/wandb_run.py", line 387, in wrapper
    return func(self, *args, **kwargs)
  File "/usr/local/lib/python3.8/dist-packages/wandb/sdk/wandb_run.py", line 435, in wrapper_fn
    return func(self, *args, **kwargs)
  File "/usr/local/lib/python3.8/dist-packages/wandb/sdk/wandb_run.py", line 1518, in _console_raw_callback
    self._backend.interface.publish_output_raw(name, data)
  File "/usr/local/lib/python3.8/dist-packages/wandb/sdk/interface/interface.py", line 761, in publish_output_raw
    self._publish_output_raw(o)
  File "/usr/local/lib/python3.8/dist-packages/wandb/sdk/interface/interface_shared.py", line 38, in _publish_output_raw
    self._publish(rec)
  File "/usr/local/lib/python3.8/dist-packages/wandb/sdk/interface/interface_sock.py", line 39, in _publish
    self._sock_client.send_record_publish(record)
  File "/usr/local/lib/python3.8/dist-packages/wandb/sdk/lib/sock_client.py", line 174, in send_record_publish
    self.send_server_request(server_req)
  File "/usr/local/lib/python3.8/dist-packages/wandb/sdk/lib/sock_client.py", line 154, in send_server_request
    self._send_message(msg)
  File "/usr/local/lib/python3.8/dist-packages/wandb/sdk/lib/sock_client.py", line 151, in _send_message
    self._sendall_with_error_handle(header + data)
  File "/usr/local/lib/python3.8/dist-packages/wandb/sdk/lib/sock_client.py", line 130, in _sendall_with_error_handle
    sent = self._sock.send(data)
BrokenPipeError: [Errno 32] Broken pipe
2025-04-07 15:39:49,778 ERROR   MainThread:784255 [redirect.py:_on_write():661] [no run ID] error in stderr callback
Traceback (most recent call last):
  File "/usr/local/lib/python3.8/dist-packages/wandb/sdk/lib/redirect.py", line 659, in _on_write
    cb(written_data)
  File "/usr/local/lib/python3.8/dist-packages/wandb/sdk/wandb_run.py", line 2381, in <lambda>
    lambda data: self._console_raw_callback("stderr", data),
  File "/usr/local/lib/python3.8/dist-packages/wandb/sdk/wandb_run.py", line 387, in wrapper
    return func(self, *args, **kwargs)
  File "/usr/local/lib/python3.8/dist-packages/wandb/sdk/wandb_run.py", line 435, in wrapper_fn
    return func(self, *args, **kwargs)
  File "/usr/local/lib/python3.8/dist-packages/wandb/sdk/wandb_run.py", line 1518, in _console_raw_callback
    self._backend.interface.publish_output_raw(name, data)
  File "/usr/local/lib/python3.8/dist-packages/wandb/sdk/interface/interface.py", line 761, in publish_output_raw
    self._publish_output_raw(o)
  File "/usr/local/lib/python3.8/dist-packages/wandb/sdk/interface/interface_shared.py", line 38, in _publish_output_raw
    self._publish(rec)
  File "/usr/local/lib/python3.8/dist-packages/wandb/sdk/interface/interface_sock.py", line 39, in _publish
    self._sock_client.send_record_publish(record)
  File "/usr/local/lib/python3.8/dist-packages/wandb/sdk/lib/sock_client.py", line 174, in send_record_publish
    self.send_server_request(server_req)
  File "/usr/local/lib/python3.8/dist-packages/wandb/sdk/lib/sock_client.py", line 154, in send_server_request
    self._send_message(msg)
  File "/usr/local/lib/python3.8/dist-packages/wandb/sdk/lib/sock_client.py", line 151, in _send_message
    self._sendall_with_error_handle(header + data)
  File "/usr/local/lib/python3.8/dist-packages/wandb/sdk/lib/sock_client.py", line 130, in _sendall_with_error_handle
    sent = self._sock.send(data)
BrokenPipeError: [Errno 32] Broken pipe
2025-04-07 15:39:49,778 ERROR   MainThread:784255 [redirect.py:_on_write():661] [no run ID] error in stderr callback
Traceback (most recent call last):
  File "/usr/local/lib/python3.8/dist-packages/wandb/sdk/lib/redirect.py", line 659, in _on_write
    cb(written_data)
  File "/usr/local/lib/python3.8/dist-packages/wandb/sdk/wandb_run.py", line 2381, in <lambda>
    lambda data: self._console_raw_callback("stderr", data),
  File "/usr/local/lib/python3.8/dist-packages/wandb/sdk/wandb_run.py", line 387, in wrapper
    return func(self, *args, **kwargs)
  File "/usr/local/lib/python3.8/dist-packages/wandb/sdk/wandb_run.py", line 435, in wrapper_fn
    return func(self, *args, **kwargs)
  File "/usr/local/lib/python3.8/dist-packages/wandb/sdk/wandb_run.py", line 1518, in _console_raw_callback
    self._backend.interface.publish_output_raw(name, data)
  File "/usr/local/lib/python3.8/dist-packages/wandb/sdk/interface/interface.py", line 761, in publish_output_raw
    self._publish_output_raw(o)
  File "/usr/local/lib/python3.8/dist-packages/wandb/sdk/interface/interface_shared.py", line 38, in _publish_output_raw
    self._publish(rec)
  File "/usr/local/lib/python3.8/dist-packages/wandb/sdk/interface/interface_sock.py", line 39, in _publish
    self._sock_client.send_record_publish(record)
  File "/usr/local/lib/python3.8/dist-packages/wandb/sdk/lib/sock_client.py", line 174, in send_record_publish
    self.send_server_request(server_req)
  File "/usr/local/lib/python3.8/dist-packages/wandb/sdk/lib/sock_client.py", line 154, in send_server_request
    self._send_message(msg)
  File "/usr/local/lib/python3.8/dist-packages/wandb/sdk/lib/sock_client.py", line 151, in _send_message
    self._sendall_with_error_handle(header + data)
  File "/usr/local/lib/python3.8/dist-packages/wandb/sdk/lib/sock_client.py", line 130, in _sendall_with_error_handle
    sent = self._sock.send(data)
BrokenPipeError: [Errno 32] Broken pipe
2025-04-07 15:39:49,778 ERROR   MainThread:784255 [redirect.py:_on_write():661] [no run ID] error in stderr callback
Traceback (most recent call last):
  File "/usr/local/lib/python3.8/dist-packages/wandb/sdk/lib/redirect.py", line 659, in _on_write
    cb(written_data)
  File "/usr/local/lib/python3.8/dist-packages/wandb/sdk/wandb_run.py", line 2381, in <lambda>
    lambda data: self._console_raw_callback("stderr", data),
  File "/usr/local/lib/python3.8/dist-packages/wandb/sdk/wandb_run.py", line 387, in wrapper
    return func(self, *args, **kwargs)
  File "/usr/local/lib/python3.8/dist-packages/wandb/sdk/wandb_run.py", line 435, in wrapper_fn
    return func(self, *args, **kwargs)
  File "/usr/local/lib/python3.8/dist-packages/wandb/sdk/wandb_run.py", line 1518, in _console_raw_callback
    self._backend.interface.publish_output_raw(name, data)
  File "/usr/local/lib/python3.8/dist-packages/wandb/sdk/interface/interface.py", line 761, in publish_output_raw
    self._publish_output_raw(o)
  File "/usr/local/lib/python3.8/dist-packages/wandb/sdk/interface/interface_shared.py", line 38, in _publish_output_raw
    self._publish(rec)
  File "/usr/local/lib/python3.8/dist-packages/wandb/sdk/interface/interface_sock.py", line 39, in _publish
    self._sock_client.send_record_publish(record)
  File "/usr/local/lib/python3.8/dist-packages/wandb/sdk/lib/sock_client.py", line 174, in send_record_publish
    self.send_server_request(server_req)
  File "/usr/local/lib/python3.8/dist-packages/wandb/sdk/lib/sock_client.py", line 154, in send_server_request
    self._send_message(msg)
  File "/usr/local/lib/python3.8/dist-packages/wandb/sdk/lib/sock_client.py", line 151, in _send_message
    self._sendall_with_error_handle(header + data)
  File "/usr/local/lib/python3.8/dist-packages/wandb/sdk/lib/sock_client.py", line 130, in _sendall_with_error_handle
    sent = self._sock.send(data)
BrokenPipeError: [Errno 32] Broken pipe
2025-04-07 15:39:49,779 ERROR   MainThread:784255 [redirect.py:_on_write():661] [no run ID] error in stderr callback
Traceback (most recent call last):
  File "/usr/local/lib/python3.8/dist-packages/wandb/sdk/lib/redirect.py", line 659, in _on_write
    cb(written_data)
  File "/usr/local/lib/python3.8/dist-packages/wandb/sdk/wandb_run.py", line 2381, in <lambda>
    lambda data: self._console_raw_callback("stderr", data),
  File "/usr/local/lib/python3.8/dist-packages/wandb/sdk/wandb_run.py", line 387, in wrapper
    return func(self, *args, **kwargs)
  File "/usr/local/lib/python3.8/dist-packages/wandb/sdk/wandb_run.py", line 435, in wrapper_fn
    return func(self, *args, **kwargs)
  File "/usr/local/lib/python3.8/dist-packages/wandb/sdk/wandb_run.py", line 1518, in _console_raw_callback
    self._backend.interface.publish_output_raw(name, data)
  File "/usr/local/lib/python3.8/dist-packages/wandb/sdk/interface/interface.py", line 761, in publish_output_raw
    self._publish_output_raw(o)
  File "/usr/local/lib/python3.8/dist-packages/wandb/sdk/interface/interface_shared.py", line 38, in _publish_output_raw
    self._publish(rec)
  File "/usr/local/lib/python3.8/dist-packages/wandb/sdk/interface/interface_sock.py", line 39, in _publish
    self._sock_client.send_record_publish(record)
  File "/usr/local/lib/python3.8/dist-packages/wandb/sdk/lib/sock_client.py", line 174, in send_record_publish
    self.send_server_request(server_req)
  File "/usr/local/lib/python3.8/dist-packages/wandb/sdk/lib/sock_client.py", line 154, in send_server_request
    self._send_message(msg)
  File "/usr/local/lib/python3.8/dist-packages/wandb/sdk/lib/sock_client.py", line 151, in _send_message
    self._sendall_with_error_handle(header + data)
  File "/usr/local/lib/python3.8/dist-packages/wandb/sdk/lib/sock_client.py", line 130, in _sendall_with_error_handle
    sent = self._sock.send(data)
BrokenPipeError: [Errno 32] Broken pipe
2025-04-07 15:39:49,779 ERROR   MainThread:784255 [redirect.py:_on_write():661] [no run ID] error in stderr callback
Traceback (most recent call last):
  File "/usr/local/lib/python3.8/dist-packages/wandb/sdk/lib/redirect.py", line 659, in _on_write
    cb(written_data)
  File "/usr/local/lib/python3.8/dist-packages/wandb/sdk/wandb_run.py", line 2381, in <lambda>
    lambda data: self._console_raw_callback("stderr", data),
  File "/usr/local/lib/python3.8/dist-packages/wandb/sdk/wandb_run.py", line 387, in wrapper
    return func(self, *args, **kwargs)
  File "/usr/local/lib/python3.8/dist-packages/wandb/sdk/wandb_run.py", line 435, in wrapper_fn
    return func(self, *args, **kwargs)
  File "/usr/local/lib/python3.8/dist-packages/wandb/sdk/wandb_run.py", line 1518, in _console_raw_callback
    self._backend.interface.publish_output_raw(name, data)
  File "/usr/local/lib/python3.8/dist-packages/wandb/sdk/interface/interface.py", line 761, in publish_output_raw
    self._publish_output_raw(o)
  File "/usr/local/lib/python3.8/dist-packages/wandb/sdk/interface/interface_shared.py", line 38, in _publish_output_raw
    self._publish(rec)
  File "/usr/local/lib/python3.8/dist-packages/wandb/sdk/interface/interface_sock.py", line 39, in _publish
    self._sock_client.send_record_publish(record)
  File "/usr/local/lib/python3.8/dist-packages/wandb/sdk/lib/sock_client.py", line 174, in send_record_publish
    self.send_server_request(server_req)
  File "/usr/local/lib/python3.8/dist-packages/wandb/sdk/lib/sock_client.py", line 154, in send_server_request
    self._send_message(msg)
  File "/usr/local/lib/python3.8/dist-packages/wandb/sdk/lib/sock_client.py", line 151, in _send_message
    self._sendall_with_error_handle(header + data)
  File "/usr/local/lib/python3.8/dist-packages/wandb/sdk/lib/sock_client.py", line 130, in _sendall_with_error_handle
    sent = self._sock.send(data)
BrokenPipeError: [Errno 32] Broken pipe
2025-04-07 15:39:49,779 ERROR   MainThread:784255 [redirect.py:_on_write():661] [no run ID] error in stderr callback
Traceback (most recent call last):
  File "/usr/local/lib/python3.8/dist-packages/wandb/sdk/lib/redirect.py", line 659, in _on_write
    cb(written_data)
  File "/usr/local/lib/python3.8/dist-packages/wandb/sdk/wandb_run.py", line 2381, in <lambda>
    lambda data: self._console_raw_callback("stderr", data),
  File "/usr/local/lib/python3.8/dist-packages/wandb/sdk/wandb_run.py", line 387, in wrapper
    return func(self, *args, **kwargs)
  File "/usr/local/lib/python3.8/dist-packages/wandb/sdk/wandb_run.py", line 435, in wrapper_fn
    return func(self, *args, **kwargs)
  File "/usr/local/lib/python3.8/dist-packages/wandb/sdk/wandb_run.py", line 1518, in _console_raw_callback
    self._backend.interface.publish_output_raw(name, data)
  File "/usr/local/lib/python3.8/dist-packages/wandb/sdk/interface/interface.py", line 761, in publish_output_raw
    self._publish_output_raw(o)
  File "/usr/local/lib/python3.8/dist-packages/wandb/sdk/interface/interface_shared.py", line 38, in _publish_output_raw
    self._publish(rec)
  File "/usr/local/lib/python3.8/dist-packages/wandb/sdk/interface/interface_sock.py", line 39, in _publish
    self._sock_client.send_record_publish(record)
  File "/usr/local/lib/python3.8/dist-packages/wandb/sdk/lib/sock_client.py", line 174, in send_record_publish
    self.send_server_request(server_req)
  File "/usr/local/lib/python3.8/dist-packages/wandb/sdk/lib/sock_client.py", line 154, in send_server_request
    self._send_message(msg)
  File "/usr/local/lib/python3.8/dist-packages/wandb/sdk/lib/sock_client.py", line 151, in _send_message
    self._sendall_with_error_handle(header + data)
  File "/usr/local/lib/python3.8/dist-packages/wandb/sdk/lib/sock_client.py", line 130, in _sendall_with_error_handle
    sent = self._sock.send(data)
BrokenPipeError: [Errno 32] Broken pipe
2025-04-07 15:39:49,779 ERROR   MainThread:784255 [redirect.py:_on_write():661] [no run ID] error in stderr callback
Traceback (most recent call last):
  File "/usr/local/lib/python3.8/dist-packages/wandb/sdk/lib/redirect.py", line 659, in _on_write
    cb(written_data)
  File "/usr/local/lib/python3.8/dist-packages/wandb/sdk/wandb_run.py", line 2381, in <lambda>
    lambda data: self._console_raw_callback("stderr", data),
  File "/usr/local/lib/python3.8/dist-packages/wandb/sdk/wandb_run.py", line 387, in wrapper
    return func(self, *args, **kwargs)
  File "/usr/local/lib/python3.8/dist-packages/wandb/sdk/wandb_run.py", line 435, in wrapper_fn
    return func(self, *args, **kwargs)
  File "/usr/local/lib/python3.8/dist-packages/wandb/sdk/wandb_run.py", line 1518, in _console_raw_callback
    self._backend.interface.publish_output_raw(name, data)
  File "/usr/local/lib/python3.8/dist-packages/wandb/sdk/interface/interface.py", line 761, in publish_output_raw
    self._publish_output_raw(o)
  File "/usr/local/lib/python3.8/dist-packages/wandb/sdk/interface/interface_shared.py", line 38, in _publish_output_raw
    self._publish(rec)
  File "/usr/local/lib/python3.8/dist-packages/wandb/sdk/interface/interface_sock.py", line 39, in _publish
    self._sock_client.send_record_publish(record)
  File "/usr/local/lib/python3.8/dist-packages/wandb/sdk/lib/sock_client.py", line 174, in send_record_publish
    self.send_server_request(server_req)
  File "/usr/local/lib/python3.8/dist-packages/wandb/sdk/lib/sock_client.py", line 154, in send_server_request
    self._send_message(msg)
  File "/usr/local/lib/python3.8/dist-packages/wandb/sdk/lib/sock_client.py", line 151, in _send_message
    self._sendall_with_error_handle(header + data)
  File "/usr/local/lib/python3.8/dist-packages/wandb/sdk/lib/sock_client.py", line 130, in _sendall_with_error_handle
    sent = self._sock.send(data)
BrokenPipeError: [Errno 32] Broken pipe
2025-04-07 15:39:49,779 ERROR   MainThread:784255 [redirect.py:_on_write():661] [no run ID] error in stderr callback
Traceback (most recent call last):
  File "/usr/local/lib/python3.8/dist-packages/wandb/sdk/lib/redirect.py", line 659, in _on_write
    cb(written_data)
  File "/usr/local/lib/python3.8/dist-packages/wandb/sdk/wandb_run.py", line 2381, in <lambda>
    lambda data: self._console_raw_callback("stderr", data),
  File "/usr/local/lib/python3.8/dist-packages/wandb/sdk/wandb_run.py", line 387, in wrapper
    return func(self, *args, **kwargs)
  File "/usr/local/lib/python3.8/dist-packages/wandb/sdk/wandb_run.py", line 435, in wrapper_fn
    return func(self, *args, **kwargs)
  File "/usr/local/lib/python3.8/dist-packages/wandb/sdk/wandb_run.py", line 1518, in _console_raw_callback
    self._backend.interface.publish_output_raw(name, data)
  File "/usr/local/lib/python3.8/dist-packages/wandb/sdk/interface/interface.py", line 761, in publish_output_raw
    self._publish_output_raw(o)
  File "/usr/local/lib/python3.8/dist-packages/wandb/sdk/interface/interface_shared.py", line 38, in _publish_output_raw
    self._publish(rec)
  File "/usr/local/lib/python3.8/dist-packages/wandb/sdk/interface/interface_sock.py", line 39, in _publish
    self._sock_client.send_record_publish(record)
  File "/usr/local/lib/python3.8/dist-packages/wandb/sdk/lib/sock_client.py", line 174, in send_record_publish
    self.send_server_request(server_req)
  File "/usr/local/lib/python3.8/dist-packages/wandb/sdk/lib/sock_client.py", line 154, in send_server_request
    self._send_message(msg)
  File "/usr/local/lib/python3.8/dist-packages/wandb/sdk/lib/sock_client.py", line 151, in _send_message
    self._sendall_with_error_handle(header + data)
  File "/usr/local/lib/python3.8/dist-packages/wandb/sdk/lib/sock_client.py", line 130, in _sendall_with_error_handle
    sent = self._sock.send(data)
BrokenPipeError: [Errno 32] Broken pipe
2025-04-07 15:39:49,780 ERROR   MainThread:784255 [redirect.py:_on_write():661] [no run ID] error in stderr callback
Traceback (most recent call last):
  File "/usr/local/lib/python3.8/dist-packages/wandb/sdk/lib/redirect.py", line 659, in _on_write
    cb(written_data)
  File "/usr/local/lib/python3.8/dist-packages/wandb/sdk/wandb_run.py", line 2381, in <lambda>
    lambda data: self._console_raw_callback("stderr", data),
  File "/usr/local/lib/python3.8/dist-packages/wandb/sdk/wandb_run.py", line 387, in wrapper
    return func(self, *args, **kwargs)
  File "/usr/local/lib/python3.8/dist-packages/wandb/sdk/wandb_run.py", line 435, in wrapper_fn
    return func(self, *args, **kwargs)
  File "/usr/local/lib/python3.8/dist-packages/wandb/sdk/wandb_run.py", line 1518, in _console_raw_callback
    self._backend.interface.publish_output_raw(name, data)
  File "/usr/local/lib/python3.8/dist-packages/wandb/sdk/interface/interface.py", line 761, in publish_output_raw
    self._publish_output_raw(o)
  File "/usr/local/lib/python3.8/dist-packages/wandb/sdk/interface/interface_shared.py", line 38, in _publish_output_raw
    self._publish(rec)
  File "/usr/local/lib/python3.8/dist-packages/wandb/sdk/interface/interface_sock.py", line 39, in _publish
    self._sock_client.send_record_publish(record)
  File "/usr/local/lib/python3.8/dist-packages/wandb/sdk/lib/sock_client.py", line 174, in send_record_publish
    self.send_server_request(server_req)
  File "/usr/local/lib/python3.8/dist-packages/wandb/sdk/lib/sock_client.py", line 154, in send_server_request
    self._send_message(msg)
  File "/usr/local/lib/python3.8/dist-packages/wandb/sdk/lib/sock_client.py", line 151, in _send_message
    self._sendall_with_error_handle(header + data)
  File "/usr/local/lib/python3.8/dist-packages/wandb/sdk/lib/sock_client.py", line 130, in _sendall_with_error_handle
    sent = self._sock.send(data)
BrokenPipeError: [Errno 32] Broken pipe
